Workbook

Sheet Processes and Flows
A1: Case Study: LCA Study of a 1-Liter Polyethylene Plastic Bottle
A2: LCIA Method: ReCiPe 2016
A5: Processes and Flows
A7: Ethylene Production
D8: Scaling factor | E8: =E14/D14 -> 0.034
B9: Input | C9: Unit | D9: Unit process flow | E9: Reference flow
A10: 1 | B10: Crude oil | C10: kg | D10: 1.45 | E10: =D10*$E$8 -> 0.0493
A11: 2 | B11: Ground water | C11: m3 | D11: 0 | E11: =D11*$E$8 -> 0
A12: 3 | B12: Energy | C12: MJ | D12: 31.263 | E12: =D12*$E$8 -> 1.062942
B13: Output
A14: P1 | B14: Ethene (ethylene) | C14: kg | D14: 1 | E14: =E27 -> 0.034
A15: 1 | B15: Carbon dioxide | C15: kg | D15: 1.1568 | E15: =D15*$E$8 -> 0.0393312
A16: 2 | B16: Methane | C16: kg | D16: 0.0075131 | E16: =D16*$E$8 -> 0.0002554454
A17: 3 | B17: Nitrogen dioxide | C17: kg | D17: 0.0021191 | E17: =D17*$E$8 -> 7.20494e-05
A18: 4 | B18: Nitrogen monoxide | C18: kg | D18: 1.527e-11 | E18: =D18*$E$8 -> 5.1918e-13
A19: 5 | B19: Sulfur dioxide | C19: kg | D19: 0.0025142 | E19: =D19*$E$8 -> 8.54828e-05
A20: 6 | B20: MNVOC | C20: kg | D20: 1.6369e-06 | E20: =D20*$E$8 -> 5.56546e-08
A21: 7 | B21: PM2.5 | C21: kg | D21: 1.0251e-07 | E21: =D21*$E$8 -> 3.48534e-09
A24: Polyethylene Granulate Production
D25: Scaling factor | E25: =E32/D32 -> 0.04
B26: Input | C26: Unit | D26: Unit process flow | E26: Reference flow
A27: P1 | B27: Ethene (ethylene) | C27: kg | D27: 0.85 | E27: =$E$25*D27 -> 0.034
A28: 1 | B28: Crude oil | C28: kg | D28: 0 | E28: =$E$25*D28 -> 0
A29: 2 | B29: Ground water | C29: m3 | D29: 0 | E29: =$E$25*D29 -> 0
A30: 3 | B30: Energy | C30: MJ | D30: 27.401 | E30: =$E$25*D30 -> 1.09604
B31: Output
A32: P2 | B32: Polyethylene granulate | C32: kg | D32: 1 | E32: =E63 -> 0.04
A33: 1 | B33: Carbon dioxide | C33: kg | D33: 1.5668 | E33: =$E$25*D33 -> 0.062672
A34: 2 | B34: Methane | C34: kg | D34: 0.014198 | E34: =$E$25*D34 -> 0.00056792
A35: 3 | B35: Nitrogen dioxide | C35: kg | D35: 0.00323 | E35: =$E$25*D35 -> 0.0001292
A36: 4 | B36: Nitrogen monoxide | C36: kg | D36: 0 | E36: =$E$25*D36 -> 0
A37: 5 | B37: Sulfur dioxide | C37: kg | D37: 0.0040765 | E37: =$E$25*D37 -> 0.00016306
A38: 6 | B38: MNVOC | C38: kg | D38: 0.00014638 | E38: =$E$25*D38 -> 5.8552e-06
A39: 7 | B39: PM2.5 | C39: kg | D39: 9.9479e-06 | E39: =$E$25*D39 -> 3.97916e-07
A42: Drinking Water Production
D43: Scaling factor | E43: =E49/D49 -> 1
B44: Input | C44: Unit | D44: Unit process flow | E44: Reference flow
A45: 1 | B45: Crude oil | C45: kg | D45: 0 | E45: 0
A46: 2 | B46: Ground water | C46: m3 | D46: 0.0010196 | E46: =$E$43*D46 -> 0.0010196
A47: 3 | B47: Energy | C47: MJ | D47: 0.013018 | E47: =$E$43*D47 -> 0.013018
...

Sheet LCI
A2: Life Cycle Inventory Tables
B3: Elementary flow | D3: Ethylene production | E3: Polyethylene granulate production | F3: Drinking water production | G3: Bottle production + water filling | H3: Transportation to customers | I3: Landfill of plastic wastes | J3: Life Cycle Inventory
A4: 1 | B4: Carbon dioxide | C4: kg | D4: {='Processes and Flows'!E15:E21} -> 0.0393312 | E4: {='Processes and Flows'!E33:E39} -> 0.062672 | F4: {='Processes and Flows'!E50:E56} -> 0.00055491 | G4: {='Processes and Flows'!E69:E75} -> 0.09 | H4: {='Processes and Flows'!E89:E95} -> 0.006651632 | I4: {='Processes and Flows'!E106:E112} -> 0.00244096 | J4: =SUM(D4:I4) -> 0.2016507
A5: 2 | B5: Methane | C5: kg | D5: 0.0002554454 | E5: 0.00056792 | F5: 6.0894e-07 | G5: 5e-09 | H5: 6.499376e-06 | I5: 1.42484e-05 | J5: =SUM(D5:I5) -> 0.00084472712
A6: 3 | B6: Nitrogen dioxide | C6: kg | D6: 7.20494e-05 | E6: 0.0001292 | F6: 1.124e-06 | G6: 3e-09 | H6: 5.60196e-05 | I6: 6.1256e-06 | J6: =SUM(D6:I6) -> 0.0002645216
A7: 4 | B7: Nitrogen monoxide | C7: kg | D7: 5.1918e-13 | E7: 0 | F7: 6.2637e-16 | G7: 5e-09 | H7: 1.445704e-14 | I7: 1.54188e-14 | J7: =SUM(D7:I7) -> 5.0005497e-09
A8: 5 | B8: Sulfur dioxide | C8: kg | D8: 8.54828e-05 | E8: 0.00016306 | F8: 6.0455e-07 | G8: 8e-09 | H8: 3.551184e-06 | I8: 5.2052e-06 | J8: =SUM(D8:I8) -> 0.00025791173
A9: 6 | B9: MNVOC | C9: kg | D9: 5.56546e-08 | E9: 5.8552e-06 | F9: 4.6995e-10 | G9: 2e-07 | H9: 1.27192e-09 | I9: 1.0176e-06 | J9: =SUM(D9:I9) -> 7.1301965e-06
A10: 7 | B10: PM2.5 | C10: kg | D10: 3.48534e-09 | E10: 3.97916e-07 | F10: 1.9429e-12 | G10: 2e-08 | H10: 1.404936e-10 | I10: 5.5104e-11 | J10: =SUM(D10:I10) -> 4.2159888e-07
A11: 8 | B11: Crude oil | C11: kg | D11: {='Processes and Flows'!E10:E12} -> 0.0493 | E11: {='Processes and Flows'!E28:E30} -> 0 | F11: {='Processes and Flows'!E45:E47} -> 0 | G11: {='Processes and Flows'!E64:E66} -> 0 | H11: {='Processes and Flows'!E84:E86} -> 0.0033072 | I11: {='Processes and Flows'!E101:E103} -> 0 | J11: =SUM(D11:I11) -> 0.0526072
A12: 9 | B12: Ground water | C12: m3 | D12: 0 | E12: 0 | F12: 0.0010196 | G12: 0 | H12: 0 | I12: 0 | J12: =SUM(D12:I12) -> 0.0010196
A13: 10 | B13: Energy | C13: MJ | D13: 1.062942 | E13: 1.09604 | F13: 0.013018 | G13: 3 | H13: 0.0904956 | I13: 0.0224224 | J13: =SUM(D13:I13) -> 5.284918

Sheet CF table
A2: Mid Point Category Characterization Factors Matrix (ReCiPe 2016)
B3: Midpoint category | D3: Characterization unit | E3: CO2 | F3: CH4 | G3: NO2 | H3: NO | I3: SO2 | J3: MNVOC | K3: PM2.5 | L3: Crude oil | M3: Ground Water
A4: 1 | B4: Climate Change (GWP100) | C4: CC | D4: kg CO2 eq | E4: 1 | F4: 34 | G4: 0 | H4: 0 | I4: 0 | J4: 0 | K4: 0 | L4: 0 | M4: 0
A5: 2 | B5: Ozone Formation, Human Health | C5: OFH | D5: kg NOx eq | E5: 0 | F5: 0 | G5: 1 | H5: 1.53 | I5: 0 | J5: 0.18 | K5: 0 | L5: 0 | M5: 0
A6: 3 | B6: Fine Particulate Matter Formation | C6: PMF | D6: kg PM2.5 eq | E6: 0 | F6: 0 | G6: 0.11 | H6: 0.17 | I6: 0.29 | J6: 0 | K6: 1 | L6: 0 | M6: 0
A7: 4 | B7: Ozone Formation, Terrestrial Ecosystems | C7: OFE | D7: kg NOx eq | E7: 0 | F7: 0 | G7: 1 | H7: 1.53 | I7: 0 | J7: 0.29 | K7: 0 | L7: 0 | M7: 0
A8: 5 | B8: Terrestrial Acidification | C8: TA | D8: kg SO2 eq | E8: 0 | F8: 0 | G8: 0.36 | H8: 0.552 | I8: 1 | J8: 0 | K8: 0 | L8: 0 | M8: 0
A9: 6 | B9: Fossil resource scarcity | C9: FRS | D9: kg oil eq | E9: 0 | F9: 0 | G9: 0 | H9: 0 | I9: 0 | J9: 0 | K9: 0 | L9: 1 | M9: 0
A10: 7 | B10: Water consumption | C10: WC | D10: m3 | E10: 0 | F10: 0 | G10: 0 | H10: 0 | I10: 0 | J10: 0 | K10: 0 | L10: 0 | M10: 1

Sheet LCIA midpoints
A3: Mid-Point Category Impact Scores
B4: Midpoint category | D4: Characterization unit | E4: Ethylene production | F4: Polyethylene granulate production | G4: Drinking water production | H4: Bottle production + water filling | I4: Transportation to customers | J4: Landfill of plastic wastes | K4: LCIA profile
A5: 1 | B5: Climate Change (GWP100) | C5: CC | D5: kg CO2 eq | E5: {=MMULT('CF table'!E4:M10,LCI!D4:J12)} -> 0.048016344 | F5: 0.08198128 | G5: 0.00057561396 | H5: 0.09000017 | I5: 0.0068726108 | J5: 0.0029254056 | K5: 0.23037142 | M5: =SUM(E5:J5) -> 0.23037142
A6: 2 | B6: Ozone Formation, Human Health | C6: OFH | D6: kg NOx eq | E6: 7.2059419e-05 | F6: 0.00013025394 | G6: 1.1240846e-06 | H6: 4.665e-08 | I6: 5.6019829e-05 | J6: 6.308768e-06 | K6: 0.00026581269 | M6: =SUM(E6:J6) -> 0.00026581269
A7: 3 | B7: Fine Particulate Matter Formation | C7: PMF | D7: kg PM2.5 eq | E7: 3.2718931e-05 | F7: 6.1897316e-05 | G7: 2.9896144e-07 | H7: 2.35e-08 | I7: 7.1921399e-06 | J7: 2.1833791e-06 | K7: 0.00010431423 | M7: =SUM(E7:J7) -> 0.00010431423
A8: 4 | B8: Ozone Formation, Terrestrial Ecosystems | C8: OFE | D8: kg NOx eq | E8: 7.2065541e-05 | F8: 0.00013089801 | G8: 1.1241363e-06 | H8: 6.865e-08 | I8: 5.6019969e-05 | J8: 6.420704e-06 | K8: 0.00026659701 | M8: =SUM(E8:J8) -> 0.00026659701
A9: 5 | B9: Terrestrial Acidification | C9: TA | D9: kg SO2 eq | E9: 0.00011142058 | F9: 0.000209572 | G9: 1.00919e-06 | H9: 1.184e-08 | I9: 2.371824e-05 | J9: 7.410416e-06 | K9: 0.00035314227 | M9: =SUM(E9:J9) -> 0.00035314227
A10: 6 | B10: Fossil resource scarcity | C10: FRS | D10: kg oil eq | E10: 0.0493 | F10: 0 | G10: 0 | H10: 0 | I10: 0.0033072 | J10: 0 | K10: 0.0526072 | M10: =SUM(E10:J10) -> 0.0526072
A11: 7 | B11: Water consumption | C11: WC | D11: m3 | E11: 0 | F11: 0 | G11: 0.0010196 | H11: 0 | I11: 0 | J11: 0 | K11: 0.0010196 | M11: =SUM(E11:J11) -> 0.0010196
B14: Energy | C14: Energy | D14: MJ | E14: {=LCI!D13:J13} -> 1.062942 | F14: 1.09604 | G14: 0.013018 | H14: 3 | I14: 0.0904956 | J14: 0.0224224 | K14: 5.284918 | M14: =SUM(E14:J14) -> 5.284918

Sheet LCIA ReCiPe endpoints
B2: Midpoint to Endpoint Characterization Factors (ReCiPe 2016)
D3: CC (GWP100) | E3: OFH | F3: PMF | G3: OFE | H3: TA | I3: FRS | J3: WC
B4: Endpoint (Hierarchic) | C4: Unit | D4: kg CO2 eq | E4: kg NOx eq | F4: kg PM2.5 eq | G4: kg NOx eq | H4: kg SO2 eq | I4: kg oil eq | J4: m3
A5: 1 | B5: Human Health | C5: DALY | D5: 9.28e-07 | E5: 9.1e-07 | F5: 0.000629 | G5: 0 | H5: 0 | I5: 0 | J5: =0.00000222 -> 2.22e-06
A6: 2a | B6: Terrestrial Ecosystems | C6: Species.year | D6: 2.8e-09 | E6: 0 | F6: 0 | G6: 1.29e-07 | H6: 2.12e-07 | I6: 0 | J6: =0.0000000135 -> 1.35e-08
A7: 2b | B7: Freshwater Ecosystems | C7: Species.year | D7: 7.65e-14 | E7: 0 | F7: 0 | G7: 0 | H7: 0 | I7: 0 | J7: =0.000000000000604 -> 6.04e-13
A8: 2c | B8: Marine Ecosystems | C8: Species.year | D8: 0 | E8: 0 | F8: 0 | G8: 0 | H8: 0 | I8: 0 | J8: 0
A9: 3 | B9: Resources | C9: USD2013 | D9: 0 | E9: 0 | F9: 0 | G9: 0 | H9: 0 | I9: 0.45656754 | J9: 0
B13: Endpoint (Hierarchic) | C13: Unit | D13: Score
A14: 1 | B14: Human Health | C14: DALY | D14: {=MMULT(D5:J9, 'LCIA midpoints'!K5:K11)} -> 2.8190373e-07
A15: 2a | B15: Terrestrial Ecosystems | C15: Species.year | D15: 7.6806176e-10
A16: 2b | B16: Freshwater Ecosystems | C16: Species.year | D16: 1.8239252e-14
A17: 2c | B17: Marine Ecosystems | C17: Species.year | D17: 0
A18: 3 | B18: Resources | C18: USD2013 | D18: 0.02401874
B21: Endpoint (Hierarchic) | C21: Unit | D21: Score
A22: 1 | B22: Human Health | C22: DALY | D22: =D14 -> 2.8190373e-07
A23: 2 | B23: Terrestrial Ecosystems | C23: Species.year | D23: =SUM(D15:D17) -> 7.6808e-10
A24: 3 | B24: Resources | C24: USD2013 | D24: =D18 -> 0.02401874
