Workbook

Sheet LED 10w
A1: Case Study: Comparative LCA study on using LED and Incandescent Lamps
A3: Funtional Unit
B4: Total hours | C4: hrs | D4: 10000
B5: Brighness | C5: lm | D5: 800
A7: LED 10w Lamp
B8: Input power | C8: kw | D8: 0.01
B9: Light output | C9: lm | D9: 800
B10: Life span | C10: hours | D10: 25000
B11: Number of lamps | C11: items | D11: =D4/D10 -> 0.4
A14: Processes and Flows (LED)
A16: Manufacturing
D17: Scaling factor | E17: =E23/D23 -> 0.4
B18: Inputs | C18: Unit | D18: Unit process flow | E18: Reference flow
A19: 1 | B19: Materials | C19: kg | D19: 0.1 | E19: =$E$17*D19 -> 0.04
A20: 2 | B20: Plastic | C20: kg | D20: 0.025 | E20: =$E$17*D20 -> 0.01
A21: 3 | B21: Electricity | C21: kWh | D21: 8.34 | E21: =$E$17*D21 -> 3.336
B22: Outputs
B23: LED (10w) lamp | C23: item | D23: 1 | E23: =D11 -> 0.4
A24: 1 | B24: CO2 | C24: kg | D24: 1.8 | E24: =$E$17*D24 -> 0.72
A25: 2 | B25: CH4 | C25: kg | D25: 0.003 | E25: =$E$17*D25 -> 0.0012
A26: 3 | B26: NH3 | C26: kg | D26: 0.0006 | E26: =$E$17*D26 -> 0.00024
A27: 4 | B27: SO2 | C27: kg | D27: 0.0085 | E27: =$E$17*D27 -> 0.0034
A28: 5 | B28: NOx | C28: kg | D28: 0.0062 | E28: =$E$17*D28 -> 0.00248
A29: 6 | B29: PM2.5 | C29: kg | D29: 0.0011 | E29: =$E$17*D29 -> 0.00044
A31: Usage
D32: Scaling factor | E32: =E34/D34 -> 0.4
B33: Inputs | C33: Unit | D33: Unit process flow | E33: Reference flow
A34: 1 | B34: Led Lamp | C34: item | D34: 1 | E34: =D11 -> 0.4
A35: 2 | B35: Electricity | C35: kWh | D35: =D8*D10 -> 250 | E35: =$E$32*D35 -> 100
B36: Outputs
B37: Lights | C37: hours | D37: =D10 -> 25000 | E37: =$E$32*D37 -> 10000
A38: 1 | B38: CO2 | C38: kg | D38: 118.75 | E38: =$E$32*D38 -> 47.5
A39: 2 | B39: CH4 | C39: kg | D39: 0.025 | E39: =$E$32*D39 -> 0.01
A40: 3 | B40: NH3 | C40: kg | D40: 0.005 | E40: =$E$32*D40 -> 0.002
A41: 4 | B41: SO2 | C41: kg | D41: 0.6 | E41: =$E$32*D41 -> 0.24
A42: 5 | B42: NOx | C42: kg | D42: 0.475 | E42: =$E$32*D42 -> 0.19
A43: 6 | B43: PM2.5 | C43: kg | D43: 0.0625 | E43: =$E$32*D43 -> 0.025
A45: End of Life (Recycle)
D46: Scaling factor | E46: =E48/D48 -> 0.4
B47: Inputs | D47: Unit process flow | E47: Reference flow
...

Sheet Incand 60w
A1: Case Study: Comparative LCA study on using LED and Incandescent Lamps
A3: Funtional Unit
B4: Total hours | C4: hrs | D4: 10000
B5: Brighness | C5: lm | D5: 800
A7: Incandescent Lamp 60w
B8: Input | C8: kw | D8: 0.06
B9: Light output | C9: Lumens | D9: 800
B10: Life span | C10: hours | D10: 1000
B11: Number of lamps | C11: items | D11: =D4/D10 -> 10
A14: Processes and Flows for Incandescent Lamp
A16: Manufacturing
D17: Scaling factor | E17: =E23/D23 -> 10
B18: Inputs | C18: Unit | D18: Unit process flow | E18: Reference flow
A19: 1 | B19: Materials | C19: kg | D19: 0.006 | E19: =$E$17*D19 -> 0.06
A20: 2 | B20: Glass | C20: kg | D20: 0.014 | E20: =$E$17*D20 -> 0.14
A21: 3 | B21: Electricity | C21: kwH | D21: 1.4 | E21: =$E$17*D21 -> 14
B22: Outputs
B23: Incand lamp 60w | C23: item | D23: 1 | E23: =D11 -> 10
A24: 1 | B24: CO2 | C24: kg | D24: 0.3 | E24: =$E$17*D24 -> 3
A25: 2 | B25: CH4 | C25: kg | D25: 0.0005 | E25: =$E$17*D25 -> 0.005
A26: 3 | B26: NH3 | C26: kg | D26: 0.0001 | E26: =$E$17*D26 -> 0.001
A27: 4 | B27: SO2 | C27: kg | D27: 0.0012 | E27: =$E$17*D27 -> 0.012
A28: 5 | B28: Nox | C28: kg | D28: 0.0008 | E28: =$E$17*D28 -> 0.008
A29: 6 | B29: PM2.5 | C29: kg | D29: 0.0002 | E29: =$E$17*D29 -> 0.002
A31: Usage
D32: Scaling factor | E32: =E34/D34 -> 10
B33: Inputs | C33: Unit | D33: Unit process flow | E33: Reference flow
A34: 1 | B34: Lamp | C34: item | D34: 1 | E34: =D11 -> 10
A35: 2 | B35: Electricity | C35: kWh | D35: =D8*D10 -> 60 | E35: =$E$32*D35 -> 600
B36: Outputs
B37: Lights | C37: hours | D37: =D10 -> 1000 | E37: =$E$32*D37 -> 10000
A38: 1 | B38: CO2 | C38: kg | D38: 28.5 | E38: =$E$32*D38 -> 285
A39: 2 | B39: CH4 | C39: kg | D39: 0.006 | E39: =$E$32*D39 -> 0.06
A40: 3 | B40: NH3 | C40: kg | D40: 0.0012 | E40: =$E$32*D40 -> 0.012
A41: 4 | B41: SO2 | C41: kg | D41: 0.144 | E41: =$E$32*D41 -> 1.44
A42: 5 | B42: Nox | C42: kg | D42: 0.114 | E42: =$E$32*D42 -> 1.14
A43: 6 | B43: PM2.5 | C43: kg | D43: 0.015 | E43: =$E$32*D43 -> 0.15
A45: End of Life (Recycle)
D46: Scaling factor | E46: =E48/D48 -> 10
B47: Inputs | C47: Unit | D47: Unit process flow | E47: Reference flow
...

Sheet midpoint scores
A2: Emission/Extraction to Mid Point Characterization Factors
B4: Midpoint Impact Category | D4: Unit | E4: CO2 | F4: CH4 | G4: NH3 | H4: SO2 | I4: NOx | J4: PM2.5
A5: 1 | B5: Climate Change (GWP100) | C5: CC | D5: kg CO₂ eq | E5: 1 | F5: 34 | G5: 0 | H5: 0 | I5: 0 | J5: 0
A6: 2 | B6: Fine Particulate Matter Formation | C6: PMF | D6: kg PM2.5 eq | E6: 0 | F6: 0 | G6: 0.24 | H6: 0.29 | I6: 0.11 | J6: 1
A7: 3 | B7: Terrestrial Acidification | C7: TA | D7: kg SO₂ eq | E7: 0 | F7: 0 | G7: 1.96 | H7: 1 | I7: 0.36 | J7: 0
A8: 4 | B8: Marine Eutrophication | C8: ME | D8: kg N eq | E8: 0 | F8: 0 | G8: 0.24446 | H8: 0 | I8: 0.09024 | J8: 0
A9: 5 | B9: Ozone Formation – Human Health | C9: OFH | D9: kg NOₓ eq | E9: 0 | F9: 0 | G9: 0 | H9: 0 | I9: 1 | J9: 0
A10: 6 | B10: Ozone Formation – Terrestrial Ecosystems | C10: OFE | D10: kg NOₓ eq | E10: 0 | F10: 0 | G10: 0 | H10: 0 | I10: 1 | J10: 0
A13: Mid-Point Category Impact Scores LED lamp
B15: Midpoint Impact Category | D15: Unit | E15: Manufacture | F15: Usage | G15: End-of-Life | H15: LC inventory | I15: Normalized | K15: chk sum
A16: 1 | B16: Climate Change (GWP100) | C16: CC | D16: kg CO₂ eq | E16: {=MMULT('midpoint scores'!E5:J10, 'LED 10w'!D62:G67)} -> 0.7608 | F16: 47.84 | G16: 0.0688896 | H16: 48.66969 | I16: =H16/normalization!C6 -> 0.0060086037 | K16: =SUM(E16:G16) -> 48.66969
A17: 2 | B17: Fine Particulate Matter Formation | C17: PMF | D17: kg PM2.5 eq | E17: 0.0017564 | F17: 0.11598 | G17: 0.0001330112 | H17: 0.11786941 | I17: =H17/normalization!C7 -> 0.0073668382 | K17: =SUM(E17:G17) -> 0.11786941
A18: 3 | B18: Terrestrial Acidification | C18: TA | D18: kg SO₂ eq | E18: 0.0047632 | F18: 0.31232 | G18: 0.0004497408 | H18: 0.31753294 | I18: =H18/normalization!C8 -> 0.0077447059 | K18: =SUM(E18:G18) -> 0.31753294
A19: 4 | B19: Marine Eutrophication | C19: ME | D19: kg N eq | E19: 0.0002824656 | F19: 0.01763452 | G19: 2.5393709e-05 | H19: 0.017942379 | I19: =H19/normalization!C9 -> 0.0021617324 | K19: =SUM(E19:G19) -> 0.017942379
A20: 5 | B20: Ozone Formation – Human Health | C20: OFH | D20: kg NOₓ eq | E20: 0.00248 | F20: 0.19 | G20: 0.0002736 | H20: 0.1927536 | I20: =H20/normalization!C10 -> 0.0062178581 | K20: =SUM(E20:G20) -> 0.1927536
A21: 6 | B21: Ozone Formation – Terrestrial Ecosystems | C21: OFE | D21: kg NOₓ eq | E21: 0.00248 | F21: 0.19 | G21: 0.0002736 | H21: 0.1927536 | I21: =H21/normalization!C11 -> 0.0068840571 | K21: =SUM(E21:G21) -> 0.1927536
A24: Mid-Point Category Impact Scores for Incandescent Lamp
B26: Midpoint Impact Category | D26: Unit | E26: Manufacture | F26: Usage | G26: End-of-Life | H26: LC inventory | I26: Normalized
A27: 1 | B27: Climate Change (GWP100) | C27: CC | D27: kg CO₂ eq | E27: {=MMULT('midpoint scores'!E5:J10, 'Incand 60w'!D62:G67)} -> 3.17 | F27: 287.04 | G27: 0.1196 | H27: 290.3296 | I27: =H27/normalization!C6 -> 0.03584316 | N27: =SUM(E27:G27) -> 290.3296
A28: 2 | B28: Fine Particulate Matter Formation | C28: PMF | D28: kg PM2.5 eq | E28: 0.0066 | F28: 0.69588 | G28: 0.00028995 | H28: 0.70276995 | I28: =H28/normalization!C7 -> 0.043923122 | N28: =SUM(E28:G28) -> 0.70276995
A29: 3 | B29: Terrestrial Acidification | C29: TA | D29: kg SO₂ eq | E29: 0.01684 | F29: 1.87392 | G29: 0.0007808 | H29: 1.8915408 | I29: =H29/normalization!C8 -> 0.046135141 | N29: =SUM(E29:G29) -> 1.8915408
A30: 4 | B30: Marine Eutrophication | C30: ME | D30: kg N eq | E30: 0.00096638 | F30: 0.10580712 | G30: 4.40863e-05 | H30: 0.10681759 | I30: =H30/normalization!C9 -> 0.012869589 | N30: =SUM(E30:G30) -> 0.10681759
A31: 5 | B31: Ozone Formation – Human Health | C31: OFH | D31: kg NOₓ eq | E31: 0.008 | F31: 1.14 | G31: 0.000475 | H31: 1.148475 | I31: =H31/normalization!C10 -> 0.037047581 | N31: =SUM(E31:G31) -> 1.148475
A32: 6 | B32: Ozone Formation – Terrestrial Ecosystems | C32: OFE | D32: kg NOₓ eq | E32: 0.008 | F32: 1.14 | G32: 0.000475 | H32: 1.148475 | I32: =H32/normalization!C11 -> 0.041016964 | N32: =SUM(E32:G32) -> 1.148475

Sheet normalization
A2: Normalization Reference Values
B5: Midpoint Category | C5: Normalization reference (World, H, 2010) | D5: Unit
A6: 1 | B6: Climate Change (GWP100) | C6: 8100 | D6: kg CO₂ eq/person·yr
A7: 2 | B7: Fine Particulate Matter Formation | C7: 16 | D7: kg PM₂.₅ eq/person·yr
A8: 3 | B8: Terrestrial Acidification | C8: 41 | D8: kg SO₂ eq/person·yr
A9: 4 | B9: Marine Eutrophication | C9: 8.3 | D9: kg N eq/person·yr
A10: 5 | B10: Ozone Formation – Human Health | C10: 31 | D10: kg NOₓ eq/person·yr
A11: 6 | B11: Ozone Formation – Terrestrial Ecosystems | C11: 28 | D11: kg NOₓ eq/person·yr
B14: Endpoint category | C14: Normalization reference (World, H, 2010) | D14: Unit
A15: 1 | B15: Human Health | C15: 0.024 | D15: DALY/person·yr
A16: 2 | B16: Ecosystems | C16: 0.000148 | D16: species·yr/person·yr
A17: 3 | B17: Resource Scarcity | C17: 989 | D17: USD2013/person·yr

Sheet endpoint scores
A2: Mid-point to End point characterization factors
C4: Climate Change (GWP100) | D4: Fine Particulate Matter Formation | E4: Terrestrial Acidification | F4: Marine Eutrophication | G4: Ozone Formation – Human Health | H4: Ozone Formation – Terrestrial Ecosystems | J4: Weights
A5: 1 | B5: Human health | C5: 9.28e-07 | D5: 0.000629 | E5: 0 | F5: 0 | G5: 9.1e-07 | H5: 0 | J5: 0.4
A6: 2(a) | B6: Terrestrial ecosystems | C6: 2.8e-09 | D6: 0 | E6: 2.12e-07 | F6: 0 | G6: 0 | H6: 1.29e-07 | J6: 0.3
A7: 2(b) | B7: Freshwater ecosystems | C7: 7.65e-14 | D7: 0 | E7: 0 | F7: 0 | G7: 0 | H7: 0 | J7: 0.1
A8: 2(c) | B8: Marine ecosystems | C8: 0 | D8: 0 | E8: 0 | F8: 1.7e-09 | G8: 0 | H8: 0 | J8: 0.1
A9: 3 | B9: Resources | C9: 0 | D9: 0 | E9: 0 | F9: 0 | G9: 0 | H9: 0 | J9: 0.1
A12: End-point scores for LED lamp
B14: Endpoint protection | C14: Unit | D14: Endpoint score | E14: Total | G14: Normalized | H14: Total | J14: Weighted
A15: 1 | B15: Human health | C15: DALY | D15: {=MMULT(C5:H9, 'midpoint scores'!H16:H21)} -> 0.00011948074 | E15: =D15 -> 0.00011948074 | G15: =E15/normalization!C15 -> 0.0049783641 | H15: =G15 -> 0.0049783641 | J15: =J5*G15 -> 0.0019913456
A16: 2(a) | B16: Terrestrial ecosystems | D16: 2.2845733e-07 | G16: =D16/normalization!C16 -> 0.0015436306 | J16: =J6*G16 -> 0.00046308918
A17: 2(b) | B17: Freshwater ecosystems | C17: species.yr | D17: 3.7232313e-12 | E17: =SUM(D16:D18) -> 2.2849155e-07 | G17: =D17/normalization!C16 -> 2.5156968e-08 | H17: =SUM(G16:G18) -> 0.0015438619 | J17: =J7*G17 -> 2.5156968e-09
A18: 2(c) | B18: Marine ecosystems | D18: 3.0502045e-11 | G18: =D18/normalization!C16 -> 2.060949e-07 | J18: =J8*G18 -> 2.060949e-08
A19: 3 | B19: Resources | C19: USD2013 | D19: 0 | E19: =D19 -> 0 | G19: =D19/normalization!C17 -> 0 | H19: =G19 -> 0 | J19: =J9*G19 -> 0
J20: =SUM(J15:J19) -> 0.0024544579
J21: =SUMPRODUCT(J5:J9, G15:G19) -> 0.0024544579
A22: End-point scores for Incandescent Lamp
B24: Endpoint protection | C24: Unit | D24: Endpoint score | E24: Total | G24: Normalized | H24: Total | J24: Weighted
A25: 1 | B25: Human health | C25: DALY | D25: {=MMULT(C5:H9, 'midpoint scores'!H27:H32)} -> 0.00071251328 | E25: =D25 -> 0.00071251328 | G25: =D25/normalization!C15 -> 0.029688053 | H25: =G25 -> 0.029688053 | J25: =J5*G25 -> 0.011875221
A26: 2(a) | B26: Terrestrial ecosystems | D26: 1.3620828e-06 | G26: =D26/normalization!C16 -> 0.0092032622 | J26: =J6*G26 -> 0.0027609787
A27: 2(b) | B27: Freshwater ecosystems | C27: species.yr | D27: 2.2210214e-11 | E27: =SUM(D26:D28) -> 1.3622866e-06 | G27: =D27/normalization!C16 -> 1.5006902e-07 | H27: =SUM(G26:G28) -> 0.0092046392 | J27: =J7*G27 -> 1.5006902e-08
A28: 2(c) | B28: Marine ecosystems | D28: 1.815899e-10 | G28: =D28/normalization!C16 -> 1.2269588e-06 | J28: =J8*G28 -> 1.2269588e-07
A29: 3 | B29: Resources | C29: USD2013 | D29: 0 | E29: =D29 -> 0 | G29: =D29/normalization!C17 -> 0 | H29: =G29 -> 0 | J29: =J9*G29 -> 0
J30: =SUM(J25:J29) -> 0.014636338
J31: =SUMPRODUCT(J5:J9,G25:G29) -> 0.014636338
